Workbook

Sheet Cómo usarlo
A1: CAPÍTULO 17 · MATERIAL PRÁCTICO
A2: Plan de 90 días
A3: Material complementario de «Vende más y trabaja menos»
A6: 1. Plan de 90 días
B7: Escribe la fecha de inicio, un lunes, y la hoja calcula las fechas de cada semana. Asigna un responsable a cada tarea y ve marcando su estado. Arriba verás el porcentaje del plan completado.
B8: Cada fase se apoya en la anterior: no te saltes ninguna, aunque puedes alargarlas si lo necesitas.
A10: 2. Hoja de seguimiento
B11: Úsala en cada reunión semanal de quince minutos: tarea, responsable, indicador, fecha límite y si está hecha.
A13: 3. Los quince pasos
B14: Dentro de cada flujo que automatices, sigue siempre este orden. Hay una columna para cada flujo.
A16: Cuando algo se tuerza
B17: Mueve, no abandones: si una semana no se cumple, desplaza esa tarea, pero mantén la reunión semanal.
B18: Protege el piloto: es tu prueba de que funciona; termínalo antes de empezar nada nuevo.
B19: Reduce el alcance antes que el plazo: mejor un flujo funcionando a tiempo que tres a medias.
B21: Las celdas en amarillo claro son para rellenar. Las demás se calculan solas.
B23: Material complementario del libro «Vende más y trabaja menos», de Jacob Ruiz. © 2026 Jacob Ruiz. Uso libre en tu empresa; no se permite su venta ni su distribución como material propio.

Sheet Plan de 90 días
A1: CAPÍTULO 17 · MATERIAL PRÁCTICO
A2: El plan de 90 días
A3: Todo el libro convertido en un calendario semana a semana
A4: Fecha de inicio (un lunes)
A5: Plan completado | C5: =IF(COUNTA(D8:D23)=0,0,COUNTIF(H8:H23,"Hecho")/COUNTA(D8:D23))
A7: Semanas | B7: Desde | C7: Hasta | D7: Qué hacer | E7: Capítulos | F7: Entregable | G7: Responsable | H7: Estado | I7: Notas
A8: Fase 1 · Diagnóstico
A9: 1 | B9: =IF($C$4="","",$C$4+0) | C9: =IF($C$4="","",$C$4+4) | D9: Autodiagnóstico con el equipo y hoja de coste del trabajo manual, o diagnóstico externo si lo necesitas | E9: 1, 15 | F9: Puntuación por bloques y cinco tareas con su coste | H9: Pendiente
A10: 2 | B10: =IF($C$4="","",$C$4+7) | C10: =IF($C$4="","",$C$4+11) | D10: Recorrido del cliente, fugas, matriz impacto-esfuerzo y objetivos | E10: 2 | F10: Flujo piloto elegido y objetivos medibles | H10: Pendiente
A11: Fase 2 · Base
A12: 3 | B12: =IF($C$4="","",$C$4+14) | C12: =IF($C$4="","",$C$4+18) | D12: Inventario de herramientas, elección o revisión del CRM y taller de diseño con el equipo | E12: 11, 7, 16 | F12: CRM decidido y conectado con la web | H12: Pendiente
A13: 4 | B13: =IF($C$4="","",$C$4+21) | C13: =IF($C$4="","",$C$4+25) | D13: Etapas del embudo, limpieza de datos, segmentos y consentimientos | E13: 7, 3, 13 | F13: Embudo configurado y base de datos limpia | H13: Pendiente
A14: Fase 3 · Primeros flujos
A15: 5 y 6 | B15: =IF($C$4="","",$C$4+28) | C15: =IF($C$4="","",$C$4+39) | D15: Flujo piloto: respuesta inmediata, alta en CRM y aviso al comercial; formación práctica de quienes lo usan | E15: 4, 7, 16 | F15: Piloto funcionando, medido y equipo formado | H15: Pendiente
A16: 7 | B16: =IF($C$4="","",$C$4+42) | C16: =IF($C$4="","",$C$4+46) | D16: Seguimiento automático de presupuestos | E16: 7 | F16: Recordatorios a los 3 y 7 días | H16: Pendiente
A17: 8 | B17: =IF($C$4="","",$C$4+49) | C17: =IF($C$4="","",$C$4+53) | D17: Secuencia de bienvenida | E17: 5 | F17: Tres correos automáticos | H17: Pendiente
A18: 9 | B18: =IF($C$4="","",$C$4+56) | C18: =IF($C$4="","",$C$4+60) | D18: Encuesta NPS tras la compra y avisos de renovación | E18: 8 | F18: Encuesta y calendario de avisos activos | H18: Pendiente
A19: 10 | B19: =IF($C$4="","",$C$4+63) | C19: =IF($C$4="","",$C$4+67) | D19: Preguntas frecuentes, primera tarea con IA, inventario de IA y formación básica en IA del equipo | E19: 9, 10, 14, 16 | F19: Respuestas rápidas, una tarea con IA en prueba, inventario hecho y equipo formado | H19: Pendiente
A20: Fase 4 · Medir y ampliar
A21: 11 | B21: =IF($C$4="","",$C$4+70) | C21: =IF($C$4="","",$C$4+74) | D21: Cuadro de mando y primera reunión mensual | E21: 12 | F21: Cuadro de mando con datos reales | H21: Pendiente
A22: 12 | B22: =IF($C$4="","",$C$4+77) | C22: =IF($C$4="","",$C$4+81) | D22: Ajustes según los datos y pruebas A/B | E22: 12 | F22: Dos mejoras aplicadas | H22: Pendiente
A23: 13 | B23: =IF($C$4="","",$C$4+84) | C23: =IF($C$4="","",$C$4+88) | D23: Revisión de los 90 días y plan del siguiente trimestre | E23: 17 | F23: Resultados presentados y nuevo plan | H23: Pendiente

Sheet Hoja de seguimiento
A1: CAPÍTULO 17 · MATERIAL PRÁCTICO
A2: Hoja de seguimiento
A3: Para la reunión semanal de quince minutos
A5: Semana | B5: Semana del | C5: Tarea | D5: Responsable | E5: Indicador | F5: Fecha límite | G5: Hecho | H5: Comentarios
A6: 1 | B6: =IF('Plan de 90 días'!$C$4="","",'Plan de 90 días'!$C$4+0)
A7: 1 | B7: =IF('Plan de 90 días'!$C$4="","",'Plan de 90 días'!$C$4+0)
A8: 1 | B8: =IF('Plan de 90 días'!$C$4="","",'Plan de 90 días'!$C$4+0)
A9: 1 | B9: =IF('Plan de 90 días'!$C$4="","",'Plan de 90 días'!$C$4+0)
A10: 2 | B10: =IF('Plan de 90 días'!$C$4="","",'Plan de 90 días'!$C$4+7)
A11: 2 | B11: =IF('Plan de 90 días'!$C$4="","",'Plan de 90 días'!$C$4+7)
A12: 2 | B12: =IF('Plan de 90 días'!$C$4="","",'Plan de 90 días'!$C$4+7)
A13: 2 | B13: =IF('Plan de 90 días'!$C$4="","",'Plan de 90 días'!$C$4+7)
A14: 3 | B14: =IF('Plan de 90 días'!$C$4="","",'Plan de 90 días'!$C$4+14)
A15: 3 | B15: =IF('Plan de 90 días'!$C$4="","",'Plan de 90 días'!$C$4+14)
A16: 3 | B16: =IF('Plan de 90 días'!$C$4="","",'Plan de 90 días'!$C$4+14)
A17: 3 | B17: =IF('Plan de 90 días'!$C$4="","",'Plan de 90 días'!$C$4+14)
A18: 4 | B18: =IF('Plan de 90 días'!$C$4="","",'Plan de 90 días'!$C$4+21)
A19: 4 | B19: =IF('Plan de 90 días'!$C$4="","",'Plan de 90 días'!$C$4+21)
A20: 4 | B20: =IF('Plan de 90 días'!$C$4="","",'Plan de 90 días'!$C$4+21)
A21: 4 | B21: =IF('Plan de 90 días'!$C$4="","",'Plan de 90 días'!$C$4+21)
A22: 5 | B22: =IF('Plan de 90 días'!$C$4="","",'Plan de 90 días'!$C$4+28)
A23: 5 | B23: =IF('Plan de 90 días'!$C$4="","",'Plan de 90 días'!$C$4+28)
A24: 5 | B24: =IF('Plan de 90 días'!$C$4="","",'Plan de 90 días'!$C$4+28)
A25: 5 | B25: =IF('Plan de 90 días'!$C$4="","",'Plan de 90 días'!$C$4+28)
A26: 6 | B26: =IF('Plan de 90 días'!$C$4="","",'Plan de 90 días'!$C$4+35)
A27: 6 | B27: =IF('Plan de 90 días'!$C$4="","",'Plan de 90 días'!$C$4+35)
A28: 6 | B28: =IF('Plan de 90 días'!$C$4="","",'Plan de 90 días'!$C$4+35)
A29: 6 | B29: =IF('Plan de 90 días'!$C$4="","",'Plan de 90 días'!$C$4+35)
A30: 7 | B30: =IF('Plan de 90 días'!$C$4="","",'Plan de 90 días'!$C$4+42)
A31: 7 | B31: =IF('Plan de 90 días'!$C$4="","",'Plan de 90 días'!$C$4+42)
A32: 7 | B32: =IF('Plan de 90 días'!$C$4="","",'Plan de 90 días'!$C$4+42)
A33: 7 | B33: =IF('Plan de 90 días'!$C$4="","",'Plan de 90 días'!$C$4+42)
A34: 8 | B34: =IF('Plan de 90 días'!$C$4="","",'Plan de 90 días'!$C$4+49)
A35: 8 | B35: =IF('Plan de 90 días'!$C$4="","",'Plan de 90 días'!$C$4+49)
A36: 8 | B36: =IF('Plan de 90 días'!$C$4="","",'Plan de 90 días'!$C$4+49)
A37: 8 | B37: =IF('Plan de 90 días'!$C$4="","",'Plan de 90 días'!$C$4+49)
A38: 9 | B38: =IF('Plan de 90 días'!$C$4="","",'Plan de 90 días'!$C$4+56)
A39: 9 | B39: =IF('Plan de 90 días'!$C$4="","",'Plan de 90 días'!$C$4+56)
A40: 9 | B40: =IF('Plan de 90 días'!$C$4="","",'Plan de 90 días'!$C$4+56)
A41: 9 | B41: =IF('Plan de 90 días'!$C$4="","",'Plan de 90 días'!$C$4+56)
...

Sheet Quince pasos
A1: CAPÍTULO 17 · MATERIAL PRÁCTICO
A2: Quince pasos que no puedes saltarte
A3: Marca cada paso en cada flujo que automatices
A5: N.º | B5: Paso | C5: Flujo 1 | D5: Flujo 2 | E5: Flujo 3
B6: Nombre del flujo
A7: 1 | B7: Define el objetivo específico del flujo.
A8: 2 | B8: Identifica el proceso que vas a automatizar y sus pasos actuales.
A9: 3 | B9: Elige la herramienta o comprueba que la que tienes lo permite.
A10: 4 | B10: Analiza los datos y define a qué segmento se dirige.
A11: 5 | B11: Diseña el flujo: pasos, disparadores, mensajes y puntos de decisión.
A12: 6 | B12: Crea el contenido: correos, mensajes y textos.
A13: 7 | B13: Forma a las personas que intervienen.
A14: 8 | B14: Configura la automatización.
A15: 9 | B15: Pruébalo tú mismo como si fueras el cliente.
A16: 10 | B16: Ponlo en marcha con un grupo pequeño antes de abrirlo a todos.
A17: 11 | B17: Mide desde el primer día.
A18: 12 | B18: Analiza los resultados frente al objetivo.
... A21: 15 | B21: Ajusta la estrategia si cambian las necesidades.
B22: Pasos completados | C22: =COUNTIF(C7:C21,"Hecho")&" de 15" | D22: =COUNTIF(D7:D21,"Hecho")&" de 15" | E22: =COUNTIF(E7:E21,"Hecho")&" de 15"
